Workbook

Sheet Summary
A1: BA Capstone Project: Checkpoint 4 — Predictive Analytics Model
A2: Retail & Sales Analytics: Customer Segmentation & Purchase Behavior Analysis | BED 106 Business Analytics | A.Y. 2026–2027, 1st Semester
A4: Item | B4: Value
A5: Technique | B5: Multiple linear regression (extends the Checkpoint 2 simple regression)
A6: Output (Y) | B6: Invoice Value (£) of a completed order
A7: Predictor X1 | B7: Lines per invoice (number of distinct products)
A8: Predictor X2 | B8: Total quantity of units on the invoice
A9: Sample | B9: 271 completed invoices, 1–3 Dec 2010 (source: Checkpoint 3 powerbi_data CSVs)
A10: Fitted equation | B10: =Regression!A22 -> Invoice Value = 52.65 + 7.20 × Lines + 0.946 × Quantity
A11: R Square | B11: =Regression!B6 -> 0.80184512
A12: Adjusted R Square | B12: =Regression!B7 -> 0.80036635
A13: Standard error of Y (£) | B13: =Regression!B8 -> 299.02765
A14: Significance F | B14: =Regression!F17 -> 6.2898298e-95
A15: Checkpoint 2 simple model R² | B15: =Regression!B25 -> 0.4777231
A16: Improvement in R² | B16: =Regression!D26 -> 0.32412203
A17: Mean absolute error (£) | B17: =Diagnostics!B16 -> 151.84571
A19: Sheets
A20: Regression — LINEST output, ANOVA, coefficients, model comparison
A21: Predictions — calculator and scenarios (editable inputs)
A22: Diagnostics — residual, outlier and multicollinearity checks
A23: Charts — actual vs predicted, residual plot
A24: Model Data / Invoice Lines — data behind every formula
A26: Data note: values in 'Invoice Lines' are copied from the group's Checkpoint 3 CSV exports (hard inputs); every statistic is a live formula.

Sheet Invoice Lines
A1: Invoice Lines — completed orders only
A2: Source: Checkpoint 3 powerbi_data/invoice_items.csv, filtered to the 271 non-cancelled invoices in invoices.csv. LineTotal = Quantity × UnitPrice (formula).
A4: InvoiceNo | B4: StockCode | C4: Quantity | D4: UnitPrice (£) | E4: LineTotal (£)
A5: 536365 | B5: 85123A | C5: 6 | D5: 2.55 | E5: =C5*D5 -> 15.3
A6: 536365 | B6: 71053 | C6: 6 | D6: 3.39 | E6: =C6*D6 -> 20.34
A7: 536365 | B7: 84406B | C7: 8 | D7: 2.75 | E7: =C7*D7 -> 22
A8: 536365 | B8: 84029G | C8: 6 | D8: 3.39 | E8: =C8*D8 -> 20.34
A9: 536365 | B9: 84029E | C9: 6 | D9: 3.39 | E9: =C9*D9 -> 20.34
A10: 536365 | B10: 22752 | C10: 2 | D10: 7.65 | E10: =C10*D10 -> 15.3
A11: 536365 | B11: 21730 | C11: 6 | D11: 4.25 | E11: =C11*D11 -> 25.5
A12: 536366 | B12: 22633 | C12: 6 | D12: 1.85 | E12: =C12*D12 -> 11.1
A13: 536366 | B13: 22632 | C13: 6 | D13: 1.85 | E13: =C13*D13 -> 11.1
A14: 536367 | B14: 48187 | C14: 4 | D14: 7.95 | E14: =C14*D14 -> 31.8
A15: 536367 | B15: 21777 | C15: 4 | D15: 7.95 | E15: =C15*D15 -> 31.8
A16: 536367 | B16: 21755 | C16: 3 | D16: 5.95 | E16: =C16*D16 -> 17.85
... A5059: 536849 | B5059: 22728 | C5059: 39 | D5059: 3.75 | E5059: =C5059*D5059 -> 146.25

Sheet Model Data
A1: Model Data — one row per completed invoice (n = 271)
A2: Lines, Quantity, Value and Avg Price are formulas over 'Invoice Lines'. Predicted and Residual use the coefficients on the 'Regression' sheet.
A4: InvoiceNo | B4: CustomerID | C4: Country | D4: Invoice Date | E4: X1: Lines (products) | F4: X2: Total Quantity | G4: Avg Unit Price (£) | H4: Y: Invoice Value (£) | I4: Predicted Y (£) | J4: Residual (£)
A5: 536365 | B5: 17850 | C5: United Kingdom | D5: 40513.351 | E5: =COUNTIFS('Invoice Lines'!$A$5:$A$5059,A5) -> 7 | F5: =SUMIFS('Invoice Lines'!$C$5:$C$5059,'Invoice Lines'!$A$5:$A$5059,A5) -> 40 | G5: =AVERAGEIFS('Invoice Lines'!$D$5:$D$5059,'Invoice Lines'!$A$5:$A$5059,A5) -> 3.91 | H5: =SUMIFS('Invoice Lines'!$E$5:$E$5059,'Invoice Lines'!$A$5:$A$5059,A5) -> 139.12 | I5: =Regression!$B$14+Regression!$B$12*E5+Regression!$B$13*F5 -> 140.90553 | J5: =H5-I5 -> -1.7855301
A6: 536366 | B6: 17850 | C6: United Kingdom | D6: 40513.353 | E6: =COUNTIFS('Invoice Lines'!$A$5:$A$5059,A6) -> 2 | F6: =SUMIFS('Invoice Lines'!$C$5:$C$5059,'Invoice Lines'!$A$5:$A$5059,A6) -> 12 | G6: =AVERAGEIFS('Invoice Lines'!$D$5:$D$5059,'Invoice Lines'!$A$5:$A$5059,A6) -> 1.85 | H6: =SUMIFS('Invoice Lines'!$E$5:$E$5059,'Invoice Lines'!$A$5:$A$5059,A6) -> 22.2 | I6: =Regression!$B$14+Regression!$B$12*E6+Regression!$B$13*F6 -> 78.408008 | J6: =H6-I6 -> -56.208008
A7: 536367 | B7: 13047 | C7: United Kingdom | D7: 40513.357 | E7: =COUNTIFS('Invoice Lines'!$A$5:$A$5059,A7) -> 12 | F7: =SUMIFS('Invoice Lines'!$C$5:$C$5059,'Invoice Lines'!$A$5:$A$5059,A7) -> 83 | G7: =AVERAGEIFS('Invoice Lines'!$D$5:$D$5059,'Invoice Lines'!$A$5:$A$5059,A7) -> 4.8533333 | H7: =SUMIFS('Invoice Lines'!$E$5:$E$5059,'Invoice Lines'!$A$5:$A$5059,A7) -> 278.73 | I7: =Regression!$B$14+Regression!$B$12*E7+Regression!$B$13*F7 -> 217.59408 | J7: =H7-I7 -> 61.135919
A8: 536368 | B8: 13047 | C8: United Kingdom | D8: 40513.357 | E8: =COUNTIFS('Invoice Lines'!$A$5:$A$5059,A8) -> 4 | F8: =SUMIFS('Invoice Lines'!$C$5:$C$5059,'Invoice Lines'!$A$5:$A$5059,A8) -> 15 | G8: =AVERAGEIFS('Invoice Lines'!$D$5:$D$5059,'Invoice Lines'!$A$5:$A$5059,A8) -> 4.775 | H8: =SUMIFS('Invoice Lines'!$E$5:$E$5059,'Invoice Lines'!$A$5:$A$5059,A8) -> 70.05 | I8: =Regression!$B$14+Regression!$B$12*E8+Regression!$B$13*F8 -> 95.649254 | J8: =H8-I8 -> -25.599254
A9: 536369 | B9: 13047 | C9: United Kingdom | D9: 40513.358 | E9: =COUNTIFS('Invoice Lines'!$A$5:$A$5059,A9) -> 1 | F9: =SUMIFS('Invoice Lines'!$C$5:$C$5059,'Invoice Lines'!$A$5:$A$5059,A9) -> 3 | G9: =AVERAGEIFS('Invoice Lines'!$D$5:$D$5059,'Invoice Lines'!$A$5:$A$5059,A9) -> 5.95 | H9: =SUMIFS('Invoice Lines'!$E$5:$E$5059,'Invoice Lines'!$A$5:$A$5059,A9) -> 17.85 | I9: =Regression!$B$14+Regression!$B$12*E9+Regression!$B$13*F9 -> 62.69187 | J9: =H9-I9 -> -44.84187
A10: 536370 | B10: 12583 | C10: France | D10: 40513.365 | E10: =COUNTIFS('Invoice Lines'!$A$5:$A$5059,A10) -> 19 | F10: =SUMIFS('Invoice Lines'!$C$5:$C$5059,'Invoice Lines'!$A$5:$A$5059,A10) -> 446 | G10: =AVERAGEIFS('Invoice Lines'!$D$5:$D$5059,'Invoice Lines'!$A$5:$A$5059,A10) -> 1.9626316 | H10: =SUMIFS('Invoice Lines'!$E$5:$E$5059,'Invoice Lines'!$A$5:$A$5059,A10) -> 801.86 | I10: =Regression!$B$14+Regression!$B$12*E10+Regression!$B$13*F10 -> 611.42763 | J10: =H10-I10 -> 190.43237
A11: 536371 | B11: 13748 | C11: United Kingdom | D11: 40513.375 | E11: =COUNTIFS('Invoice Lines'!$A$5:$A$5059,A11) -> 1 | F11: =SUMIFS('Invoice Lines'!$C$5:$C$5059,'Invoice Lines'!$A$5:$A$5059,A11) -> 80 | G11: =AVERAGEIFS('Invoice Lines'!$D$5:$D$5059,'Invoice Lines'!$A$5:$A$5059,A11) -> 2.55 | H11: =SUMIFS('Invoice Lines'!$E$5:$E$5059,'Invoice Lines'!$A$5:$A$5059,A11) -> 204 | I11: =Regression!$B$14+Regression!$B$12*E11+Regression!$B$13*F11 -> 135.53915 | J11: =H11-I11 -> 68.460845
A12: 536372 | B12: 17850 | C12: United Kingdom | D12: 40513.376 | E12: =COUNTIFS('Invoice Lines'!$A$5:$A$5059,A12) -> 2 | F12: =SUMIFS('Invoice Lines'!$C$5:$C$5059,'Invoice Lines'!$A$5:$A$5059,A12) -> 12 | G12: =AVERAGEIFS('Invoice Lines'!$D$5:$D$5059,'Invoice Lines'!$A$5:$A$5059,A12) -> 1.85 | H12: =SUMIFS('Invoice Lines'!$E$5:$E$5059,'Invoice Lines'!$A$5:$A$5059,A12) -> 22.2 | I12: =Regression!$B$14+Regression!$B$12*E12+Regression!$B$13*F12 -> 78.408008 | J12: =H12-I12 -> -56.208008
A13: 536373 | B13: 17850 | C13: United Kingdom | D13: 40513.376 | E13: =COUNTIFS('Invoice Lines'!$A$5:$A$5059,A13) -> 16 | F13: =SUMIFS('Invoice Lines'!$C$5:$C$5059,'Invoice Lines'!$A$5:$A$5059,A13) -> 88 | G13: =AVERAGEIFS('Invoice Lines'!$D$5:$D$5059,'Invoice Lines'!$A$5:$A$5059,A13) -> 3.319375 | H13: =SUMIFS('Invoice Lines'!$E$5:$E$5059,'Invoice Lines'!$A$5:$A$5059,A13) -> 259.86 | I13: =Regression!$B$14+Regression!$B$12*E13+Regression!$B$13*F13 -> 251.1305 | J13: =H13-I13 -> 8.7294952
A14: 536374 | B14: 15100 | C14: United Kingdom | D14: 40513.381 | E14: =COUNTIFS('Invoice Lines'!$A$5:$A$5059,A14) -> 1 | F14: =SUMIFS('Invoice Lines'!$C$5:$C$5059,'Invoice Lines'!$A$5:$A$5059,A14) -> 32 | G14: =AVERAGEIFS('Invoice Lines'!$D$5:$D$5059,'Invoice Lines'!$A$5:$A$5059,A14) -> 10.95 | H14: =SUMIFS('Invoice Lines'!$E$5:$E$5059,'Invoice Lines'!$A$5:$A$5059,A14) -> 350.4 | I14: =Regression!$B$14+Regression!$B$12*E14+Regression!$B$13*F14 -> 90.127861 | J14: =H14-I14 -> 260.27214
A15: 536375 | B15: 17850 | C15: United Kingdom | D15: 40513.397 | E15: =COUNTIFS('Invoice Lines'!$A$5:$A$5059,A15) -> 16 | F15: =SUMIFS('Invoice Lines'!$C$5:$C$5059,'Invoice Lines'!$A$5:$A$5059,A15) -> 88 | G15: =AVERAGEIFS('Invoice Lines'!$D$5:$D$5059,'Invoice Lines'!$A$5:$A$5059,A15) -> 3.319375 | H15: =SUMIFS('Invoice Lines'!$E$5:$E$5059,'Invoice Lines'!$A$5:$A$5059,A15) -> 259.86 | I15: =Regression!$B$14+Regression!$B$12*E15+Regression!$B$13*F15 -> 251.1305 | J15: =H15-I15 -> 8.7294952
A16: 536376 | B16: 15291 | C16: United Kingdom | D16: 40513.397 | E16: =COUNTIFS('Invoice Lines'!$A$5:$A$5059,A16) -> 2 | F16: =SUMIFS('Invoice Lines'!$C$5:$C$5059,'Invoice Lines'!$A$5:$A$5059,A16) -> 112 | G16: =AVERAGEIFS('Invoice Lines'!$D$5:$D$5059,'Invoice Lines'!$A$5:$A$5059,A16) -> 3 | H16: =SUMIFS('Invoice Lines'!$E$5:$E$5059,'Invoice Lines'!$A$5:$A$5059,A16) -> 328.8 | I16: =Regression!$B$14+Regression!$B$12*E16+Regression!$B$13*F16 -> 173.01487 | J16: =H16-I16 -> 155.78513
... A87: 536542 | B87: 16456 | C87: United Kingdom | D87: 40513.591 | E87: =COUNTIFS('Invoice Lines'!$A$5:$A$5059,A87) -> 16 | F87: =SUMIFS('Invoice Lines'!$C$5:$C$5059,'Invoice Lines'!$A$5:$A$5059,A87) -> 392 | G87: =AVERAGEIFS('Invoice Lines'!$D$5:$D$5059,'Invoice Lines'!$A$5:$A$5059,A87) -> 1.965625 | H87: =SUMIFS('Invoice Lines'!$E$5:$E$5059,'Invoice Lines'!$A$5:$A$5059,A87) -> 787.4 | I87: =Regression!$B$14+Regression!$B$12*E87+Regression!$B$13*F87 -> 538.73537 | J87: =H87-I87 -> 248.66463
A88: 536544 | D88: 40513.606 | E88: =COUNTIFS('Invoice Lines'!$A$5:$A$5059,A88) -> 526 | F88: =SUMIFS('Invoice Lines'!$C$5:$C$5059,'Invoice Lines'!$A$5:$A$5059,A88) -> 1207 | G88: =AVERAGEIFS('Invoice Lines'!$D$5:$D$5059,'Invoice Lines'!$A$5:$A$5059,A88) -> 4.5968631 | H88: =SUMIFS('Invoice Lines'!$E$5:$E$5059,'Invoice Lines'!$A$5:$A$5059,A88) -> 4951.37 | I88: =Regression!$B$14+Regression!$B$12*E88+Regression!$B$13*F88 -> 4982.5565 | J88: =H88-I88 -> -31.186537
A89: 536551 | B89: 17346 | C89: United Kingdom | D89: 40513.607 | E89: =COUNTIFS('Invoice Lines'!$A$5:$A$5059,A89) -> 31 | F89: =SUMIFS('Invoice Lines'!$C$5:$C$5059,'Invoice Lines'!$A$5:$A$5059,A89) -> 84 | G89: =AVERAGEIFS('Invoice Lines'!$D$5:$D$5059,'Invoice Lines'!$A$5:$A$5059,A89) -> 2.1380645 | H89: =SUMIFS('Invoice Lines'!$E$5:$E$5059,'Invoice Lines'!$A$5:$A$5059,A89) -> 134.11 | I89: =Regression!$B$14+Regression!$B$12*E89+Regression!$B$13*F89 -> 355.36903 | J89: =H89-I89 -> -221.25903
A90: 536555 | D90: 40513.609 | E90: =COUNTIFS('Invoice Lines'!$A$5:$A$5059,A90) -> 2 | F90: =SUMIFS('Invoice Lines'!$C$5:$C$5059,'Invoice Lines'!$A$5:$A$5059,A90) -> 2 | G90: =AVERAGEIFS('Invoice Lines'!$D$5:$D$5059,'Invoice Lines'!$A$5:$A$5059,A90) -> 1.485 | H90: =SUMIFS('Invoice Lines'!$E$5:$E$5059,'Invoice Lines'!$A$5:$A$5059,A90) -> 2.97 | I90: =Regression!$B$14+Regression!$B$12*E90+Regression!$B$13*F90 -> 68.947322 | J90: =H90-I90 -> -65.977322
A91: 536556 | B91: 17643 | C91: United Kingdom | D91: 40513.61 | E91: =COUNTIFS('Invoice Lines'!$A$5:$A$5059,A91) -> 8 | F91: =SUMIFS('Invoice Lines'!$C$5:$C$5059,'Invoice Lines'!$A$5:$A$5059,A91) -> 71 | G91: =AVERAGEIFS('Invoice Lines'!$D$5:$D$5059,'Invoice Lines'!$A$5:$A$5059,A91) -> 4.01875 | H91: =SUMIFS('Invoice Lines'!$E$5:$E$5059,'Invoice Lines'!$A$5:$A$5059,A91) -> 101.55 | I91: =Regression!$B$14+Regression!$B$12*E91+Regression!$B$13*F91 -> 177.43518 | J91: =H91-I91 -> -75.885178
A92: 536557 | B92: 17841 | C92: United Kingdom | D92: 40513.612 | E92: =COUNTIFS('Invoice Lines'!$A$5:$A$5059,A92) -> 64 | F92: =SUMIFS('Invoice Lines'!$C$5:$C$5059,'Invoice Lines'!$A$5:$A$5059,A92) -> 198 | G92: =AVERAGEIFS('Invoice Lines'!$D$5:$D$5059,'Invoice Lines'!$A$5:$A$5059,A92) -> 3.8553125 | H92: =SUMIFS('Invoice Lines'!$E$5:$E$5059,'Invoice Lines'!$A$5:$A$5059,A92) -> 532.43 | I92: =Regression!$B$14+Regression!$B$12*E92+Regression!$B$13*F92 -> 700.87102 | J92: =H92-I92 -> -168.44102
A93: 536558 | D93: 40513.617 | E93: =COUNTIFS('Invoice Lines'!$A$5:$A$5059,A93) -> 1 | F93: =SUMIFS('Invoice Lines'!$C$5:$C$5059,'Invoice Lines'!$A$5:$A$5059,A93) -> 5 | G93: =AVERAGEIFS('Invoice Lines'!$D$5:$D$5059,'Invoice Lines'!$A$5:$A$5059,A93) -> 19.95 | H93: =SUMIFS('Invoice Lines'!$E$5:$E$5059,'Invoice Lines'!$A$5:$A$5059,A93) -> 99.75 | I93: =Regression!$B$14+Regression!$B$12*E93+Regression!$B$13*F93 -> 64.584008 | J93: =H93-I93 -> 35.165992
A94: 536559 | B94: 17873 | C94: United Kingdom | D94: 40513.621 | E94: =COUNTIFS('Invoice Lines'!$A$5:$A$5059,A94) -> 8 | F94: =SUMIFS('Invoice Lines'!$C$5:$C$5059,'Invoice Lines'!$A$5:$A$5059,A94) -> 117 | G94: =AVERAGEIFS('Invoice Lines'!$D$5:$D$5059,'Invoice Lines'!$A$5:$A$5059,A94) -> 2.1625 | H94: =SUMIFS('Invoice Lines'!$E$5:$E$5059,'Invoice Lines'!$A$5:$A$5059,A94) -> 204.95 | I94: =Regression!$B$14+Regression!$B$12*E94+Regression!$B$13*F94 -> 220.95433 | J94: =H94-I94 -> -16.004334
A95: 536560 | B95: 13093 | C95: United Kingdom | D95: 40513.625 | E95: =COUNTIFS('Invoice Lines'!$A$5:$A$5059,A95) -> 13 | F95: =SUMIFS('Invoice Lines'!$C$5:$C$5059,'Invoice Lines'!$A$5:$A$5059,A95) -> 256 | G95: =AVERAGEIFS('Invoice Lines'!$D$5:$D$5059,'Invoice Lines'!$A$5:$A$5059,A95) -> 5.1807692 | H95: =SUMIFS('Invoice Lines'!$E$5:$E$5059,'Invoice Lines'!$A$5:$A$5059,A95) -> 799.4 | I95: =Regression!$B$14+Regression!$B$12*E95+Regression!$B$13*F95 -> 388.46547 | J95: =H95-I95 -> 410.93453
A96: 536561 | B96: 12921 | C96: United Kingdom | D96: 40513.629 | E96: =COUNTIFS('Invoice Lines'!$A$5:$A$5059,A96) -> 15 | F96: =SUMIFS('Invoice Lines'!$C$5:$C$5059,'Invoice Lines'!$A$5:$A$5059,A96) -> 140 | G96: =AVERAGEIFS('Invoice Lines'!$D$5:$D$5059,'Invoice Lines'!$A$5:$A$5059,A96) -> 2.4833333 | H96: =SUMIFS('Invoice Lines'!$E$5:$E$5059,'Invoice Lines'!$A$5:$A$5059,A96) -> 322.4 | I96: =Regression!$B$14+Regression!$B$12*E96+Regression!$B$13*F96 -> 293.12455 | J96: =H96-I96 -> 29.275447
A97: 536562 | B97: 13468 | C97: United Kingdom | D97: 40513.631 | E97: =COUNTIFS('Invoice Lines'!$A$5:$A$5059,A97) -> 18 | F97: =SUMIFS('Invoice Lines'!$C$5:$C$5059,'Invoice Lines'!$A$5:$A$5059,A97) -> 99 | G97: =AVERAGEIFS('Invoice Lines'!$D$5:$D$5059,'Invoice Lines'!$A$5:$A$5059,A97) -> 5.0166667 | H97: =SUMIFS('Invoice Lines'!$E$5:$E$5059,'Invoice Lines'!$A$5:$A$5059,A97) -> 308.65 | I97: =Regression!$B$14+Regression!$B$12*E97+Regression!$B$13*F97 -> 275.9403 | J97: =H97-I97 -> 32.7097
A98: 536563 | B98: 17760 | C98: United Kingdom | D98: 40513.631 | E98: =COUNTIFS('Invoice Lines'!$A$5:$A$5059,A98) -> 9 | F98: =SUMIFS('Invoice Lines'!$C$5:$C$5059,'Invoice Lines'!$A$5:$A$5059,A98) -> 165 | G98: =AVERAGEIFS('Invoice Lines'!$D$5:$D$5059,'Invoice Lines'!$A$5:$A$5059,A98) -> 2.6244444 | H98: =SUMIFS('Invoice Lines'!$E$5:$E$5059,'Invoice Lines'!$A$5:$A$5059,A98) -> 172.54 | I98: =Regression!$B$14+Regression!$B$12*E98+Regression!$B$13*F98 -> 273.56715 | J98: =H98-I98 -> -101.02715
A99: 536564 | B99: 13468 | C99: United Kingdom | D99: 40513.631 | E99: =COUNTIFS('Invoice Lines'!$A$5:$A$5059,A99) -> 2 | F99: =SUMIFS('Invoice Lines'!$C$5:$C$5059,'Invoice Lines'!$A$5:$A$5059,A99) -> 12 | G99: =AVERAGEIFS('Invoice Lines'!$D$5:$D$5059,'Invoice Lines'!$A$5:$A$5059,A99) -> 5.7 | H99: =SUMIFS('Invoice Lines'!$E$5:$E$5059,'Invoice Lines'!$A$5:$A$5059,A99) -> 51.4 | I99: =Regression!$B$14+Regression!$B$12*E99+Regression!$B$13*F99 -> 78.408008 | J99: =H99-I99 -> -27.008008
A100: 536565 | D100: 40513.635 | E100: =COUNTIFS('Invoice Lines'!$A$5:$A$5059,A100) -> 2 | F100: =SUMIFS('Invoice Lines'!$C$5:$C$5059,'Invoice Lines'!$A$5:$A$5059,A100) -> 2 | G100: =AVERAGEIFS('Invoice Lines'!$D$5:$D$5059,'Invoice Lines'!$A$5:$A$5059,A100) -> 3.35 | H100: =SUMIFS('Invoice Lines'!$E$5:$E$5059,'Invoice Lines'!$A$5:$A$5059,A100) -> 6.7 | I100: =Regression!$B$14+Regression!$B$12*E100+Regression!$B$13*F100 -> 68.947322 | J100: =H100-I100 -> -62.247322
A101: 536566 | B101: 16928 | C101: United Kingdom | D101: 40513.64 | E101: =COUNTIFS('Invoice Lines'!$A$5:$A$5059,A101) -> 6 | F101: =SUMIFS('Invoice Lines'!$C$5:$C$5059,'Invoice Lines'!$A$5:$A$5059,A101) -> 93 | G101: =AVERAGEIFS('Invoice Lines'!$D$5:$D$5059,'Invoice Lines'!$A$5:$A$5059,A101) -> 1.25 | H101: =SUMIFS('Invoice Lines'!$E$5:$E$5059,'Invoice Lines'!$A$5:$A$5059,A101) -> 116.25 | I101: =Regression!$B$14+Regression!$B$12*E101+Regression!$B$13*F101 -> 183.84565 | J101: =H101-I101 -> -67.595647
A102: 536567 | B102: 16048 | C102: United Kingdom | D102: 40513.644 | E102: =COUNTIFS('Invoice Lines'!$A$5:$A$5059,A102) -> 7 | F102: =SUMIFS('Invoice Lines'!$C$5:$C$5059,'Invoice Lines'!$A$5:$A$5059,A102) -> 132 | G102: =AVERAGEIFS('Invoice Lines'!$D$5:$D$5059,'Invoice Lines'!$A$5:$A$5059,A102) -> 1.7928571 | H102: =SUMIFS('Invoice Lines'!$E$5:$E$5059,'Invoice Lines'!$A$5:$A$5059,A102) -> 251.4 | I102: =Regression!$B$14+Regression!$B$12*E102+Regression!$B$13*F102 -> 227.94384 | J102: =H102-I102 -> 23.456156
A103: 536568 | B103: 16048 | C103: United Kingdom | D103: 40513.644 | E103: =COUNTIFS('Invoice Lines'!$A$5:$A$5059,A103) -> 1 | F103: =SUMIFS('Invoice Lines'!$C$5:$C$5059,'Invoice Lines'!$A$5:$A$5059,A103) -> 12 | G103: =AVERAGEIFS('Invoice Lines'!$D$5:$D$5059,'Invoice Lines'!$A$5:$A$5059,A103) -> 0.42 | H103: =SUMIFS('Invoice Lines'!$E$5:$E$5059,'Invoice Lines'!$A$5:$A$5059,A103) -> 5.04 | I103: =Regression!$B$14+Regression!$B$12*E103+Regression!$B$13*F103 -> 71.206488 | J103: =H103-I103 -> -66.166488
A104: 536569 | B104: 16274 | C104: United Kingdom | D104: 40513.649 | E104: =COUNTIFS('Invoice Lines'!$A$5:$A$5059,A104) -> 63 | F104: =SUMIFS('Invoice Lines'!$C$5:$C$5059,'Invoice Lines'!$A$5:$A$5059,A104) -> 151 | G104: =AVERAGEIFS('Invoice Lines'!$D$5:$D$5059,'Invoice Lines'!$A$5:$A$5059,A104) -> 4.1301587 | H104: =SUMIFS('Invoice Lines'!$E$5:$E$5059,'Invoice Lines'!$A$5:$A$5059,A104) -> 331.55 | I104: =Regression!$B$14+Regression!$B$12*E104+Regression!$B$13*F104 -> 649.20427 | J104: =H104-I104 -> -317.65427
A105: 536570 | B105: 14496 | C105: United Kingdom | D105: 40513.649 | E105: =COUNTIFS('Invoice Lines'!$A$5:$A$5059,A105) -> 5 | F105: =SUMIFS('Invoice Lines'!$C$5:$C$5059,'Invoice Lines'!$A$5:$A$5059,A105) -> 86 | G105: =AVERAGEIFS('Invoice Lines'!$D$5:$D$5059,'Invoice Lines'!$A$5:$A$5059,A105) -> 5.358 | H105: =SUMIFS('Invoice Lines'!$E$5:$E$5059,'Invoice Lines'!$A$5:$A$5059,A105) -> 304.34 | I105: =Regression!$B$14+Regression!$B$12*E105+Regression!$B$13*F105 -> 170.02165 | J105: =H105-I105 -> 134.31835
A106: 536571 | B106: 14696 | C106: United Kingdom | D106: 40513.651 | E106: =COUNTIFS('Invoice Lines'!$A$5:$A$5059,A106) -> 18 | F106: =SUMIFS('Invoice Lines'!$C$5:$C$5059,'Invoice Lines'!$A$5:$A$5059,A106) -> 284 | G106: =AVERAGEIFS('Invoice Lines'!$D$5:$D$5059,'Invoice Lines'!$A$5:$A$5059,A106) -> 2.3216667 | H106: =SUMIFS('Invoice Lines'!$E$5:$E$5059,'Invoice Lines'!$A$5:$A$5059,A106) -> 294.62 | I106: =Regression!$B$14+Regression!$B$12*E106+Regression!$B$13*F106 -> 450.963 | J106: =H106-I106 -> -156.343
A107: 536572 | B107: 16539 | C107: United Kingdom | D107: 40513.653 | E107: =COUNTIFS('Invoice Lines'!$A$5:$A$5059,A107) -> 21 | F107: =SUMIFS('Invoice Lines'!$C$5:$C$5059,'Invoice Lines'!$A$5:$A$5059,A107) -> 301 | G107: =AVERAGEIFS('Invoice Lines'!$D$5:$D$5059,'Invoice Lines'!$A$5:$A$5059,A107) -> 2.4071429 | H107: =SUMIFS('Invoice Lines'!$E$5:$E$5059,'Invoice Lines'!$A$5:$A$5059,A107) -> 442.35 | I107: =Regression!$B$14+Regression!$B$12*E107+Regression!$B$13*F107 -> 488.65072 | J107: =H107-I107 -> -46.300723
A108: 536573 | B108: 17025 | C108: United Kingdom | D108: 40513.656 | E108: =COUNTIFS('Invoice Lines'!$A$5:$A$5059,A108) -> 4 | F108: =SUMIFS('Invoice Lines'!$C$5:$C$5059,'Invoice Lines'!$A$5:$A$5059,A108) -> 136 | G108: =AVERAGEIFS('Invoice Lines'!$D$5:$D$5059,'Invoice Lines'!$A$5:$A$5059,A108) -> 0.9775 | H108: =SUMIFS('Invoice Lines'!$E$5:$E$5059,'Invoice Lines'!$A$5:$A$5059,A108) -> 143.12 | I108: =Regression!$B$14+Regression!$B$12*E108+Regression!$B$13*F108 -> 210.12356 | J108: =H108-I108 -> -67.003558
A109: 536574 | B109: 17025 | C109: United Kingdom | D109: 40513.657 | E109: =COUNTIFS('Invoice Lines'!$A$5:$A$5059,A109) -> 1 | F109: =SUMIFS('Invoice Lines'!$C$5:$C$5059,'Invoice Lines'!$A$5:$A$5059,A109) -> 3 | G109: =AVERAGEIFS('Invoice Lines'!$D$5:$D$5059,'Invoice Lines'!$A$5:$A$5059,A109) -> 5.95 | H109: =SUMIFS('Invoice Lines'!$E$5:$E$5059,'Invoice Lines'!$A$5:$A$5059,A109) -> 17.85 | I109: =Regression!$B$14+Regression!$B$12*E109+Regression!$B$13*F109 -> 62.69187 | J109: =H109-I109 -> -44.84187
A110: 536575 | B110: 13777 | C110: United Kingdom | D110: 40513.667 | E110: =COUNTIFS('Invoice Lines'!$A$5:$A$5059,A110) -> 8 | F110: =SUMIFS('Invoice Lines'!$C$5:$C$5059,'Invoice Lines'!$A$5:$A$5059,A110) -> 858 | G110: =AVERAGEIFS('Invoice Lines'!$D$5:$D$5059,'Invoice Lines'!$A$5:$A$5059,A110) -> 2.09875 | H110: =SUMIFS('Invoice Lines'!$E$5:$E$5059,'Invoice Lines'!$A$5:$A$5059,A110) -> 1552.98 | I110: =Regression!$B$14+Regression!$B$12*E110+Regression!$B$13*F110 -> 921.99119 | J110: =H110-I110 -> 630.98881
A111: 536576 | B111: 13777 | C111: United Kingdom | D111: 40513.674 | E111: =COUNTIFS('Invoice Lines'!$A$5:$A$5059,A111) -> 16 | F111: =SUMIFS('Invoice Lines'!$C$5:$C$5059,'Invoice Lines'!$A$5:$A$5059,A111) -> 1122 | G111: =AVERAGEIFS('Invoice Lines'!$D$5:$D$5059,'Invoice Lines'!$A$5:$A$5059,A111) -> 2.30625 | H111: =SUMIFS('Invoice Lines'!$E$5:$E$5059,'Invoice Lines'!$A$5:$A$5059,A111) -> 2558.42 | I111: =Regression!$B$14+Regression!$B$12*E111+Regression!$B$13*F111 -> 1229.3655 | J111: =H111-I111 -> 1329.0545
...

Sheet Regression
A1: Task 4.1 — Multiple Linear Regression
A2: Y = Invoice Value (£) | X1 = Lines per invoice | X2 = Total quantity. Computed with LINEST (same result as the Data Analysis ToolPak).
A4: Regression statistic | B4: Value
A5: Multiple R | B5: =SQRT(B6) -> 0.89545805
A6: R Square | B6: =INDEX(LINEST('Model Data'!$H$5:$H$275,'Model Data'!$E$5:$F$275,TRUE(),TRUE()),3,1) -> 0.80184512
A7: Adjusted R Square | B7: =1-(1-B6)*(B9-1)/B10 -> 0.80036635
A8: Standard Error of Y (£) | B8: =INDEX(LINEST('Model Data'!$H$5:$H$275,'Model Data'!$E$5:$F$275,TRUE(),TRUE()),3,2) -> 299.02765
A9: Observations (n) | B9: =COUNT('Model Data'!$H$5:$H$275) -> 271
A10: Residual df | B10: =INDEX(LINEST('Model Data'!$H$5:$H$275,'Model Data'!$E$5:$F$275,TRUE(),TRUE()),4,2) -> 268
A11: Coefficient | B11: Estimate | C11: Std. Error | D11: t Stat | E11: P-value | F11: Lower 95% | G11: Upper 95%
A12: X1: Lines per invoice | B12: =INDEX(LINEST('Model Data'!$H$5:$H$275,'Model Data'!$E$5:$F$275,TRUE(),TRUE()),1,2) -> 7.2015201 | C12: =INDEX(LINEST('Model Data'!$H$5:$H$275,'Model Data'!$E$5:$F$275,TRUE(),TRUE()),2,2) -> 0.38169634 | D12: =B12/C12 -> 18.867145 | E12: =TDIST(ABS(D12),$B$10,2) -> 4.2300402e-51 | F12: =B12-TINV(0.05,$B$10)*C12 -> 6.4500153 | G12: =B12+TINV(0.05,$B$10)*C12 -> 7.9530249
A13: X2: Total quantity | B13: =INDEX(LINEST('Model Data'!$H$5:$H$275,'Model Data'!$E$5:$F$275,TRUE(),TRUE()),1,1) -> 0.94606863 | C13: =INDEX(LINEST('Model Data'!$H$5:$H$275,'Model Data'!$E$5:$F$275,TRUE(),TRUE()),2,1) -> 0.045185943 | D13: =B13/C13 -> 20.937233 | E13: =TDIST(ABS(D13),$B$10,2) -> 2.4547912e-58 | F13: =B13-TINV(0.05,$B$10)*C13 -> 0.85710405 | G13: =B13+TINV(0.05,$B$10)*C13 -> 1.0350332
A14: Intercept | B14: =INDEX(LINEST('Model Data'!$H$5:$H$275,'Model Data'!$E$5:$F$275,TRUE(),TRUE()),1,3) -> 52.652144 | C14: =INDEX(LINEST('Model Data'!$H$5:$H$275,'Model Data'!$E$5:$F$275,TRUE(),TRUE()),2,3) -> 20.951846 | D14: =B14/C14 -> 2.5130074 | E14: =TDIST(ABS(D14),$B$10,2) -> 0.012557988 | F14: =B14-TINV(0.05,$B$10)*C14 -> 11.400993 | G14: =B14+TINV(0.05,$B$10)*C14 -> 93.903296
A16: ANOVA | B16: df | C16: SS | D16: MS | E16: F | F16: Significance F
A17: Regression | B17: 2 | C17: =INDEX(LINEST('Model Data'!$H$5:$H$275,'Model Data'!$E$5:$F$275,TRUE(),TRUE()),5,1) -> 96971302 | D17: =C17/B17 -> 48485651 | E17: =INDEX(LINEST('Model Data'!$H$5:$H$275,'Model Data'!$E$5:$F$275,TRUE(),TRUE()),4,1) -> 542.23871 | F17: =FDIST(E17,B17,B18) -> 6.2898298e-95
A18: Residual | B18: =B10 -> 268 | C18: =INDEX(LINEST('Model Data'!$H$5:$H$275,'Model Data'!$E$5:$F$275,TRUE(),TRUE()),5,2) -> 23963900 | D18: =C18/B18 -> 89417.538
A19: Total | B19: =B17+B18 -> 270 | C19: =C17+C18 -> 1.209352e+08
A21: Fitted equation
A22: ="Invoice Value = "&TEXT(B14,"0.00")&" + "&TEXT(B12,"0.00")&" × Lines + "&TEXT(B13,"0.000")&" × Quantity" -> Invoice Value = 52.65 + 7.20 × Lines + 0.946 × Quantity
A24: Model comparison (same 271 invoices) | B24: R Square | C24: Adjusted R² | D24: Added value of the extra variable
A25: M1 (Checkpoint 2): Lines only | B25: =RSQ('Model Data'!$H$5:$H$275,'Model Data'!$E$5:$E$275) -> 0.4777231 | C25: =1-(1-B25)*(B$8-1)/(B$8-2) -> 0.47596475 | D25: Baseline
A26: M2 (this checkpoint): Lines + Quantity | B26: =B6 -> 0.80184512 | C26: =B7 -> 0.80036635 | D26: =B26-B25 -> 0.32412203
A27: M3: Lines + Quantity + Avg Unit Price | B27: =INDEX(LINEST('Model Data'!$H$5:$H$275,'Model Data'!$E$5:$G$275,TRUE(),TRUE()),3,1) -> 0.80276823 | C27: =1-(1-B27)*(B$8-1)/(B$8-4) -> 0.80076267 | D27: =B27-B26 -> 0.00092310895
A29: Note: 'Multiple R' etc. replicate the Excel Data Analysis ToolPak → Regression summary. Interpretation of these numbers should be written by the group in the report.

Sheet Diagnostics
A1: Assumption & Limitation Checks
A2: Quick numerical checks supporting the 'assumptions and limitations' part of Task 4.1.
A4: Check | B4: Value | C4: What to look at
A5: Mean of residuals (£) | B5: =AVERAGE('Model Data'!$J$5:$J$275) -> 3.6235058e-14 | C5: Should be ≈ 0 for OLS
A6: Std. deviation of residuals (£) | B6: =STDEV('Model Data'!$J$5:$J$275) -> 297.91809 | C6: Spread of prediction errors
A7: Largest positive residual (£) | B7: =MAX('Model Data'!$J$5:$J$275) -> 1742.9214 | C7: Biggest under-prediction
A8: Largest negative residual (£) | B8: =MIN('Model Data'!$J$5:$J$275) -> -2113.8289 | C8: Biggest over-prediction
A9: Invoices with |residual| > 2 × SE | B9: =SUMPRODUCT(--(ABS('Model Data'!$J$5:$J$275)>2*Regression!B8)) -> 13 | C9: Count of poorly predicted invoices (outliers)
A10: …as % of invoices | B10: =B9/Regression!B9 -> 0.04797048 | C10: Share of outliers
A11: Correlation: Lines vs Quantity | B11: =CORREL('Model Data'!$E$5:$E$275,'Model Data'!$F$5:$F$275) -> 0.26837559 | C11: Low = little multicollinearity between predictors
A12: VIF (1 / (1 − r²)) | B12: =1/(1-B11^2) -> 1.0776158 | C12: Values near 1 = no multicollinearity problem
A13: Max invoice value (£) | B13: =MAX('Model Data'!$H$5:$H$275) -> 6308.16 | C13: Extreme order present in the sample
A14: Mean invoice value (£) | B14: =AVERAGE('Model Data'!$H$5:$H$275) -> 391.82963 | C14: Compare with max → heavy right skew
A15: Median invoice value (£) | B15: =MEDIAN('Model Data'!$H$5:$H$275) -> 248.1 | C15: Typical invoice
A16: Mean absolute error (£) | B16: =SUMPRODUCT(ABS('Model Data'!$J$5:$J$275))/Regression!B9 -> 151.84571 | C16: Average size of a miss
A17: MAE as % of mean value | B17: =B16/B14 -> 0.38752993 | C17: Relative error
A18: Date range of sample | B18: =TEXT(MIN('Model Data'!$D$5:$D$275),"yyyy-mm-dd")&" to "&TEXT(MAX('Model Data'!$D$5:$D$275),"yyyy-mm-dd") -> 2010-12-01 to 2010-12-03 | C18: Only ~3 days of trading — limits generalisation

Sheet Predictions
A1: Prediction Calculator & Scenarios
A2: Blue cells on a cream fill are inputs — change them to predict any invoice. Prediction band = Predicted ± 1.96 × Standard Error of Y (approximate).
A4: Scenario | B4: Lines (products) | C4: Total quantity | D4: Predicted value (£) | E4: Approx. low (£) | F4: Approx. high (£)
A5: Small basket | B5: 3 | C5: 30 | D5: =Regression!$B$14+Regression!$B$12*B5+Regression!$B$13*C5 -> 102.63876 | E5: =MAX(0,D5-1.96*Regression!$B$8) -> 0 | F5: =D5+1.96*Regression!$B$8 -> 688.73297
A6: Typical basket (median invoice) | B6: 11 | C6: 106 | D6: =Regression!$B$14+Regression!$B$12*B6+Regression!$B$13*C6 -> 232.15214 | E6: =MAX(0,D6-1.96*Regression!$B$8) -> 0 | F6: =D6+1.96*Regression!$B$8 -> 818.24634
A7: Average basket | B7: =ROUND(AVERAGE('Model Data'!$E$5:$E$275),0) -> 19 | C7: =ROUND(AVERAGE('Model Data'!$F$5:$F$275),0) -> 217 | D7: =Regression!$B$14+Regression!$B$12*B7+Regression!$B$13*C7 -> 394.77792 | E7: =MAX(0,D7-1.96*Regression!$B$8) -> 0 | F7: =D7+1.96*Regression!$B$8 -> 980.87212
A8: Large basket | B8: 30 | C8: 400 | D8: =Regression!$B$14+Regression!$B$12*B8+Regression!$B$13*C8 -> 647.1252 | E8: =MAX(0,D8-1.96*Regression!$B$8) -> 61.030994 | F8: =D8+1.96*Regression!$B$8 -> 1233.2194
A9: Add 5 extra product lines to the typical basket | B9: 16 | C9: 106 | D9: =Regression!$B$14+Regression!$B$12*B9+Regression!$B$13*C9 -> 268.15974 | E9: =MAX(0,D9-1.96*Regression!$B$8) -> 0 | F9: =D9+1.96*Regression!$B$8 -> 854.25394
A10: Same lines, +100 units | B10: 11 | C10: 206 | D10: =Regression!$B$14+Regression!$B$12*B10+Regression!$B$13*C10 -> 326.759 | E10: =MAX(0,D10-1.96*Regression!$B$8) -> 0 | F10: =D10+1.96*Regression!$B$8 -> 912.85321
A12: Legend: blue text / cream fill = editable input. Scenario values are illustrative choices by the analyst (the 'typical basket' uses the sample median of 11 lines and 106 units).
A14: Your own invoice → | B14: 8 | C14: 75 | D14: =Regression!$B$14+Regression!$B$12*B14+Regression!$B$13*C14 -> 181.21945 | E14: =MAX(0,D14-1.96*Regression!$B$8) -> 0 | F14: =D14+1.96*Regression!$B$8 -> 767.31366

Sheet Charts
A1: Model Charts
A2: Actual vs. predicted invoice value, and residuals vs. predicted (check for a funnel shape = unequal spread).
